Workbook

Sheet Income Tax Calculator
A1: Income Tax Calculator - Template 2025
P2: Splitting 50%
B3: 45658 | C3: 45689 | D3: 45717 | E3: 45748 | F3: 45778 | G3: 45809 | H3: 45839 | I3: 45870 | J3: 45901 | K3: 45931 | L3: 45962 | M3: 45992 | N3: Totals | P3: USD | Q3: ZWG
A4: Revenue
A5: Turnover exc VAT (Local) | B5: {=TRANSPOSE('2025 Sales'!F2:F13)} -> 3361.5734 | C5: 7074.0741 | D5: 0 | E5: 0 | F5: 0 | G5: 19863.37 | H5: 0 | I5: 0 | J5: 0 | K5: 0 | L5: 0 | M5: 0 | N5: =SUM(B5:M5) -> 30299.017 | P5: =IF(N5="","",N5/2) -> 15149.509 | Q5: =IF(N5="","",(N5/2)*'2025 Sales'!$D$14) -> 400224.77
A6: Turnover exc VAT (Export)
A7: Total Revenue | B7: =SUM(B5:B6) -> 3361.5734 | C7: =SUM(C5:C6) -> 7074.0741 | D7: =SUM(D5:D6) -> 0 | E7: =SUM(E5:E6) -> 0 | F7: =SUM(F5:F6) -> 0 | G7: =SUM(G5:G6) -> 19863.37 | H7: =SUM(H5:H6) -> 0 | I7: =SUM(I5:I6) -> 0 | ... M7: =SUM(M5:M6) -> 0 | N7: =SUM(B7:M7) -> 30299.017 | P7: =IF(N7="","",N7/2) -> 15149.509 | Q7: =IF(N7="","",(N7/2)*'2025 Sales'!$D$14) -> 400224.77
A8: Cost of Sales | N8: =SUM(B8:M8) -> 0 | P8: =IF(N8="","",N8/2) -> 0 | Q8: =IF(N8="","",(N8/2)*'2025 Sales'!$D$14) -> 0
A9: Gross Profit | B9: =B7-B8 -> 3361.5734 | C9: =C7-C8 -> 7074.0741 | D9: =D7-D8 -> 0 | E9: =E7-E8 -> 0 | F9: =F7-F8 -> 0 | G9: =G7-G8 -> 19863.37 | H9: =H7-H8 -> 0 | I9: =I7-I8 -> 0 | ... N9: =N7-N8 -> 30299.017 | P9: =IF(N9="","",N9/2) -> 15149.509 | Q9: =IF(N9="","",(N9/2)*'2025 Sales'!$D$14) -> 400224.77
A10: GP Margin | B10: =IFERROR(B9/B7,"") -> 1 | C10: =IFERROR(C9/C7,"") -> 1 | D10: =IFERROR(D9/D7,"") | E10: =IFERROR(E9/E7,"") | F10: =IFERROR(F9/F7,"") | G10: =IFERROR(G9/G7,"") -> 1 | H10: =IFERROR(H9/H7,"") | I10: =IFERROR(I9/I7,"") | ... M10: =IFERROR(M9/M7,"") | N10: =N9/N7 -> 1
A11: Operating Expenses
A12: Utilities | B12: ='Operating Expenses 2025'!B2 -> 0 | C12: ='Operating Expenses 2025'!C2 -> 0 | D12: ='Operating Expenses 2025'!D2 -> 0 | E12: ='Operating Expenses 2025'!E2 -> 0 | F12: ='Operating Expenses 2025'!F2 -> 0 | G12: ='Operating Expenses 2025'!G2 -> 12000 | H12: ='Operating Expenses 2025'!H2 -> 0 | I12: ='Operating Expenses 2025'!I2 -> 0 | ... M12: ='Operating Expenses 2025'!M2 -> 0 | N12: =SUM(B12:M12) -> 12000 | P12: =IF(N12="","",N12/2) -> 6000 | Q12: =IF(N12="","",(N12/2)*'2025 Sales'!$D$14) -> 158510
A13: Total Employent Costs (Salaries) | B13: ='Operating Expenses 2025'!B3 -> 0 | C13: ='Operating Expenses 2025'!C3 -> 0 | D13: ='Operating Expenses 2025'!D3 -> 0 | E13: ='Operating Expenses 2025'!E3 -> 0 | F13: ='Operating Expenses 2025'!F3 -> 0 | G13: ='Operating Expenses 2025'!G3 -> 1020 | H13: ='Operating Expenses 2025'!H3 -> 0 | I13: ='Operating Expenses 2025'!I3 -> 0 | ... M13: ='Operating Expenses 2025'!M3 -> 0 | N13: =SUM(B13:M13) -> 1020 | P13: =IF(N13="","",N13/2) -> 510 | Q13: =IF(N13="","",(N13/2)*'2025 Sales'!$D$14) -> 13473.35
A14: Other Expenses | B14: ='Operating Expenses 2025'!B4 -> 0 | C14: ='Operating Expenses 2025'!C4 -> 0 | D14: ='Operating Expenses 2025'!D4 -> 0 | E14: ='Operating Expenses 2025'!E4 -> 0 | F14: ='Operating Expenses 2025'!F4 -> 0 | G14: ='Operating Expenses 2025'!G4 -> 5500 | H14: ='Operating Expenses 2025'!H4 -> 0 | I14: ='Operating Expenses 2025'!I4 -> 0 | ... M14: ='Operating Expenses 2025'!M4 -> 0 | N14: =SUM(B14:M14) -> 5500 | P14: =IF(N14="","",N14/2) -> 2750 | Q14: =IF(N14="","",(N14/2)*'2025 Sales'!$D$14) -> 72650.417
A15: Total Expenses | B15: =SUM(B12:B14) -> 0 | C15: =SUM(C12:C14) -> 0 | D15: =SUM(D12:D14) -> 0 | E15: =SUM(E12:E14) -> 0 | F15: =SUM(F12:F14) -> 0 | G15: =SUM(G12:G14) -> 18520 | H15: =SUM(H12:H14) -> 0 | I15: =SUM(I12:I14) -> 0 | ... M15: =SUM(M12:M14) -> 0 | N15: =SUM(B15:M15) -> 18520 | P15: =IF(N15="","",N15/2) -> 9260 | Q15: =IF(N15="","",(N15/2)*'2025 Sales'!$D$14) -> 244633.77
A17: Net Profit before local Interest & Tax | B17: =B9-B15 -> 3361.5734 | C17: =C9-C15 -> 7074.0741 | D17: =D9-D15 -> 0 | E17: =E9-E15 -> 0 | F17: =F9-F15 -> 0 | G17: =G9-G15 -> 1343.37 | H17: =H9-H15 -> 0 | I17: =I9-I15 -> 0 | ... N17: =N9-N15 -> 11779.017 | P17: =IF(N17="","",N17/2) -> 5889.5087 | Q17: =IF(N17="","",(N17/2)*'2025 Sales'!$D$14) -> 155591
A18: Local Interest (Expense) | N18: =SUM(B18:M18) -> 0 | P18: =IF(N18="","",N18/2) -> 0 | Q18: =IF(N18="","",(N18/2)*'2025 Sales'!$D$14) -> 0
A19: Net Profit after Interest | B19: =B17-B18 -> 3361.5734 | C19: =C17-C18 -> 7074.0741 | D19: =D17-D18 -> 0 | E19: =E17-E18 -> 0 | F19: =F17-F18 -> 0 | G19: =G17-G18 -> 1343.37 | H19: =H17-H18 -> 0 | I19: =I17-I18 -> 0 | ... N19: =N17-N18 -> 11779.017 | P19: =IF(N19="","",N19/2) -> 5889.5087 | Q19: =IF(N19="","",(N19/2)*'2025 Sales'!$D$14) -> 155591
P20: =IF(N20="","",N20/2) | Q20: =IF(N20="","",(N20/2)*'2025 Sales'!$D$14)
A21: Value of Opening Stock | P21: =IF(N21="","",N21/2) | Q21: =IF(N21="","",(N21/2)*'2025 Sales'!$D$14)
A22: Value of Closing Stock | P22: =IF(N22="","",N22/2) | Q22: =IF(N22="","",(N22/2)*'2025 Sales'!$D$14)
A23: Opening Value of Assets Excluding Stock | P23: =IF(N23="","",N23/2) | Q23: =IF(N23="","",(N23/2)*'2025 Sales'!$D$14)
A24: Additional Assets Acquired - Local Excluding Stock | B24: 2700 | P24: =IF(N24="","",N24/2) | Q24: =IF(N24="","",(N24/2)*'2025 Sales'!$D$14)
A25: Additional Assets Acquired - Imports Excluding Stock | P25: =IF(N25="","",N25/2) | Q25: =IF(N25="","",(N25/2)*'2025 Sales'!$D$14)
A26: Closing Value of Assets excluding Stock | P26: =IF(N26="","",N26/2) | Q26: =IF(N26="","",(N26/2)*'2025 Sales'!$D$14)
P27: =IF(N27="","",N27/2) | Q27: =IF(N27="","",(N27/2)*'2025 Sales'!$D$14)
A28: Capital Employed | B28: 2700 | N28: =SUM(B28:M28) -> 2700 | P28: =IF(N28="","",N28/2) -> 1350 | Q28: =IF(N28="","",(N28/2)*'2025 Sales'!$D$14) -> 35664.75
P29: =IF(N29="","",N29/2) | Q29: =IF(N29="","",(N29/2)*'2025 Sales'!$D$14)
A30: less Deductions | P30: =IF(N30="","",N30/2) | Q30: =IF(N30="","",(N30/2)*'2025 Sales'!$D$14)
A31: Capital Allowances | B31: 4500 | C31: =0.25*C28 -> 0 | D31: =0.25*D28 -> 0 | E31: =0.25*E28 -> 0 | F31: =0.25*F28 -> 0 | G31: =0.25*G28 -> 0 | H31: =0.25*H28 -> 0 | I31: =0.25*I28 -> 0 | J31: =0.25*J28 -> 0 | ... M31: =0.25*M28 -> 0 | N31: =SUM(B31:M31) -> 4500 | P31: =IF(N31="","",N31/2) -> 2250 | Q31: =IF(N31="","",(N31/2)*'2025 Sales'!$D$14) -> 59441.25
A32: Scrapping Allowances | P32: =IF(N32="","",N32/2) | Q32: =IF(N32="","",(N32/2)*'2025 Sales'!$D$14)
A33: Non-Taxable Income | P33: =IF(N33="","",N33/2) | Q33: =IF(N33="","",(N33/2)*'2025 Sales'!$D$14)
P34: =IF(N34="","",N34/2) | Q34: =IF(N34="","",(N34/2)*'2025 Sales'!$D$14)
A35: Taxable Income/Loss | B35: =B19-B31-B32-B33 -> -1138.4266 | C35: =C19-C31-C32-C33 -> 7074.0741 | D35: =D19-D31-D32-D33 -> 0 | E35: =E19-E31-E32-E33 -> 0 | F35: =F19-F31-F32-F33 -> 0 | G35: =G19-G31-G32-G33 -> 1343.37 | H35: =H19-H31-H32-H33 -> 0 | I35: =I19-I31-I32-I33 -> 0 | ... M35: =M19-M31-M32-M33 -> 0 | N35: =SUM(B35:M35) -> 7279.0174 | P35: =IF(N35="","",N35/2) -> 3639.5087 | Q35: =IF(N35="","",(N35/2)*'2025 Sales'!$D$14) -> 96149.755
P36: =IF(N36="","",N36/2)
A37: Tax 25% | B37: =IF(B35<=0,"0",B35*0.25) -> 0 | C37: =IF(C35<=0,"0",C35*0.25) -> 1768.5185 | D37: =IF(D35<=0,"0",D35*0.25) -> 0 | E37: =IF(E35<=0,"0",E35*0.25) -> 0 | F37: =IF(F35<=0,"0",F35*0.25) -> 0 | G37: =IF(G35<=0,"0",G35*0.25) -> 335.8425 | H37: =IF(H35<=0,"0",H35*0.25) -> 0 | I37: =IF(I35<=0,"0",I35*0.25) -> 0 | ... N37: =IF(N35<=0,"0",N35*0.25) -> 1819.7544 | P37: =IF(N37="","",N37/2) -> 909.87718 | Q37: =IF(N37="","",(N37/2)*'2025 Sales'!$D$14) -> 24037.439
A38: AIDS Levy 3% | B38: =0.03*B37 -> 0 | C38: =0.03*C37 -> 53.055556 | D38: =0.03*D37 -> 0 | E38: =0.03*E37 -> 0 | F38: =0.03*F37 -> 0 | G38: =0.03*G37 -> 10.075275 | H38: =0.03*H37 -> 0 | I38: =0.03*I37 -> 0 | ... N38: =0.03*N37 -> 54.592631 | P38: =IF(N38="","",N38/2) -> 27.296315 | Q38: =IF(N38="","",(N38/2)*'2025 Sales'!$D$14) -> 721.12316
A39: Tax Payable | N39: =SUM(N37:N38) -> 1874.347 | P39: =IF(N39="","",N39/2) -> 937.1735 | Q39: =IF(N39="","",(N39/2)*'2025 Sales'!$D$14) -> 24758.562
A41: QPD 1 (due 20 March) | B41: 0.1 | N41: =$N$39*B41 -> 187.4347 | P41: =IF(N41="","",N41/2) -> 93.71735 | Q41: =IF(N41="","",(N41/2)*'2025 Sales'!$D$14) -> 2475.8562
A42: QPD 2 (due 20 June) | B42: 0.25 | N42: =$N$39*B42 -> 468.58675 | P42: =IF(N42="","",N42/2) -> 234.29337 | Q42: =IF(N42="","",(N42/2)*'2025 Sales'!$D$14) -> 6189.6405
...

Sheet 2025 Sales
A1: Sales | B1: USD | C1: ZWG | D1: Exchange Rate | E1: Conversion | F1: Total Sales
A2: 45658 | B2: 2000 | C2: 36000 | D2: 26.44 | E2: =C2/D2 -> 1361.5734 | F2: =B2+E2 -> 3361.5734
A3: 45689 | B3: 5000 | C3: 56000 | D3: 27 | E3: =C3/D3 -> 2074.0741 | F3: =B3+E3 -> 7074.0741
A4: 45717 | D4: 25.44 | E4: =C4/D4 -> 0 | F4: =B4+E4 -> 0
A5: 45748 | D5: 26.46 | E5: =C5/D5 -> 0 | F5: =B5+E5 -> 0
A6: 45778 | D6: 26.46 | E6: =C6/D6 -> 0 | F6: =B6+E6 -> 0
A7: 45809 | B7: 19863.37 | D7: 26.46 | E7: =C7/D7 -> 0 | F7: =B7+E7 -> 19863.37
A8: 45839 | D8: 26.46 | E8: =C8/D8 -> 0 | F8: =B8+E8 -> 0
A9: 45870 | D9: 26.46 | E9: =C9/D9 -> 0 | F9: =B9+E9 -> 0
A10: 45901 | D10: 26.46 | E10: =C10/D10 -> 0 | F10: =B10+E10 -> 0 | G10: Forecast
A11: 45931 | D11: 26.46 | E11: =C11/D11 -> 0 | F11: =B11+E11 -> 0 | G11: Forecast
A12: 45962 | D12: 26.46 | E12: =C12/D12 -> 0 | F12: =B12+E12 -> 0 | G12: Forecast
A13: 45992 | D13: 26.46 | E13: =C13/D13 -> 0 | F13: =B13+E13 -> 0 | G13: Forecast
A14: YTD 2025 | B14: =SUM(B2:B13) -> 26863.37 | C14: =SUM(C2:C13) -> 92000 | D14: =AVERAGE(D2:D13) -> 26.418333 | E14: =SUM(E2:E13) -> 3435.6474 | F14: =SUM(F2:F13) -> 30299.017

Sheet Operating Expenses 2025
A1: Operating Expenses | B1: 45658 | C1: 45689 | D1: 45717 | E1: 45748 | F1: 45778 | G1: 45809 | H1: 45839 | I1: 45870 | J1: 45901 | K1: 45931 | L1: 45962 | M1: 45992 | N1: YTD 2025
A2: Utilities & Rentals | G2: 12000 | N2: =SUM(B2:M2) -> 12000
A3: Total Employment Costs | G3: 1020 | N3: =SUM(B3:M3) -> 1020
A4: Other Expenses | G4: 5500 | N4: =SUM(B4:M4) -> 5500
N5: =SUM(N2:N4) -> 18520

Sheet VAT Calculator
A1: VAT Calculator
A2: Month | B2: January | C2: February | D2: March | E2: April | F2: May | G2: June | H2: July | I2: August | J2: September | K2: October | L2: November | M2: December | N2: Totals
A3: Gross Revenue
A4: Gross Sales incl VAT (Local) | B4: 5000 | N4: =SUM(B4:M4) -> 5000
A5: Gross Sales incl VAT (Export) | B5: 6000 | N5: =SUM(B5:M5) -> 6000
A6: Total Gross Revenue | B6: =SUM(B4:B5) -> 11000 | C6: =SUM(C4:C5) -> 0 | D6: =SUM(D4:D5) -> 0 | E6: =SUM(E4:E5) -> 0 | F6: =SUM(F4:F5) -> 0 | G6: =SUM(G4:G5) -> 0 | H6: =SUM(H4:H5) -> 0 | I6: =SUM(I4:I5) -> 0 | ... M6: =SUM(M4:M5) -> 0 | N6: =SUM(B6:M6) -> 11000
A7: Net Revenue (Reverse Calculation)
A8: Gross Sales incl VAT (Local) | B8: =B4*(100/115) -> 4347.8261 | C8: =C4*(100/115) -> 0 | D8: =D4*(100/115) -> 0 | E8: =E4*(100/115) -> 0 | F8: =F4*(100/115) -> 0 | G8: =G4*(100/115) -> 0 | H8: =H4*(100/115) -> 0 | I8: =I4*(100/115) -> 0 | ... M8: =M4*(100/115) -> 0 | N8: =SUM(B8:M8) -> 4347.8261
A9: Gross Sales incl VAT (Export) | B9: =B5*(100/115) -> 5217.3913 | C9: =C5*(100/115) -> 0 | D9: =D5*(100/115) -> 0 | E9: =E5*(100/115) -> 0 | F9: =F5*(100/115) -> 0 | G9: =G5*(100/115) -> 0 | H9: =H5*(100/115) -> 0 | I9: =I5*(100/115) -> 0 | ... M9: =M5*(100/115) -> 0 | N9: =SUM(B9:M9) -> 5217.3913
A10: Total Net Revenue | B10: =SUM(B8:B9) -> 9565.2174 | C10: =SUM(C8:C9) -> 0 | D10: =SUM(D8:D9) -> 0 | E10: =SUM(E8:E9) -> 0 | F10: =SUM(F8:F9) -> 0 | G10: =SUM(G8:G9) -> 0 | H10: =SUM(H8:H9) -> 0 | I10: =SUM(I8:I9) -> 0 | ... M10: =SUM(M8:M9) -> 0 | N10: =SUM(B10:M10) -> 9565.2174
A12: Output VAT | B12: =B6-B10 -> 1434.7826 | C12: =C6-C10 -> 0 | D12: =D6-D10 -> 0 | E12: =E6-E10 -> 0 | F12: =F6-F10 -> 0 | G12: =G6-G10 -> 0 | H12: =H6-H10 -> 0 | I12: =I6-I10 -> 0 | ... M12: =M6-M10 -> 0 | N12: =SUM(B12:M12) -> 1434.7826
A15: Bills
A16: Bills Amount | B16: 4000 | N16: =SUM(B16:M16) -> 4000
A17: Bill of Entries | B17: 1650 | N17: =SUM(B17:M17) -> 1650
B18: =SUM(B16:B17) -> 5650 | C18: =SUM(C16:C17) -> 0 | D18: =SUM(D16:D17) -> 0 | E18: =SUM(E16:E17) -> 0 | F18: =SUM(F16:F17) -> 0 | G18: =SUM(G16:G17) -> 0 | H18: =SUM(H16:H17) -> 0 | I18: =SUM(I16:I17) -> 0 | ... N18: =SUM(N16:N17) -> 5650
A20: VAT on Bills
A21: Bills VAT | B21: 465 | N21: =SUM(B21:M21) -> 465
A22: Bill of Entries VAT | B22: 215 | N22: =SUM(B22:M22) -> 215
A23: Total VAT | B23: =SUM(B21:B22) -> 680 | C23: =SUM(C21:C22) -> 0 | D23: =SUM(D21:D22) -> 0 | E23: =SUM(E21:E22) -> 0 | F23: =SUM(F21:F22) -> 0 | G23: =SUM(G21:G22) -> 0 | H23: =SUM(H21:H22) -> 0 | I23: =SUM(I21:I22) -> 0 | ... N23: =SUM(N21:N22) -> 680
A25: Input VAT | B25: =B23 -> 680 | C25: =C23 -> 0 | D25: =D23 -> 0 | E25: =E23 -> 0 | F25: =F23 -> 0 | G25: =G23 -> 0 | H25: =H23 -> 0 | I25: =I23 -> 0 | ... N25: =N23 -> 680
A28: VAT Payable/Refundable | B28: =B12-B25 -> 754.78261 | C28: =C12-C25 -> 0 | D28: =D12-D25 -> 0 | E28: =E12-E25 -> 0 | F28: =F12-F25 -> 0 | G28: =G12-G25 -> 0 | H28: =H12-H25 -> 0 | I28: =I12-I25 -> 0 | ... N28: =N12-N25 -> 754.78261
A30: Return Submission (due 15th ) | C30: =B28 -> 754.78261 | D30: =C28 -> 0 | E30: =D28 -> 0 | F30: =E28 -> 0 | G30: =F28 -> 0 | H30: =G28 -> 0 | I30: =H28 -> 0 | J30: =I28 -> 0 | ... N30: =M28 -> 0
