Workbook

Sheet Cover
B2: ZIMBABWE REVENUE AUTHORITY
B3: ITF12C — CORPORATE INCOME TAX SELF-ASSESSMENT RETURN
B4: Income Tax Act [Chapter 23:06] | Finance Act [Chapter 23:04] | Section 37A
A6: PART 1 — TAXPAYER PARTICULARS
B7: Taxpayer Name
B8: TIN
B9: Registered Address
B10: Nature of Business / SIC
B11: Year of Assessment
B12: Financial Year End
B13: Approved Subst. Acc. Period (if applicable)
B14: Currency of Books (USD / ZiG / Both)
B15: Auditor / Accounting Firm
B16: Contact Person
B17: Contact Email
B18: Contact Phone
A20: COLOUR-CODING LEGEND
B21: Input cells — enter data here (blue text)
B22: Formula cells — do not overwrite (black text)
B23: Subtotal / total rows
B24: Reference / informational rows
A27: WORKBOOK TABS — NAVIGATION
B28: Cover | C28: Taxpayer particulars & legend
B29: Tax Computation | C29: Core profit-to-taxable-income bridge (USD & ZiG)
B30: Cap Allowances | C30: SIA, Wear & Tear schedule
B31: QPD Recon | C31: Quarterly payment date reconciliation
B32: WHT Credits | C32: Withholding tax credit register
B33: Summary | C33: Final tax liability & return sign-off

Sheet Tax Computation
C2: ITF12C — TAX COMPUTATION WORKSHEET
C3: Note | E3: USD (US$) | F3: ZiG (ZWG) | G3: Total (USD equiv)
C4: SECTION A — ACCOUNTING PROFIT / (LOSS)
C5: Profit / (Loss) before tax per financial statements | D5: 1 | G5: -9580
C6: Less: Prior-year adjustments included above | D6: 2
C7: Adjusted accounting profit / (loss) | E7: =E5-E6 -> 0 | F7: =F5-F6 -> 0 | G7: =G5-G6 -> -9580
C8: SECTION B — ADD BACKS (NON-DEDUCTIBLE EXPENDITURE)
C9: Depreciation / amortisation charged in accounts | D9: 3 | G9: 2851
C10: Penalties & interest on tax (non-deductible) | D10: 4 | G10: 4518
C11: Fines & statutory penalties | D11: 5
C12: Provisions not yet incurred / contingent liabilities | D12: 6
C13: Entertainment (non-deductible portion) | D13: 7
C14: Donations exceeding prescribed limit | D14: 8
C15: Related-party expenses disallowed (thin cap / TP) | D15: 9
C16: Other non-deductible expenditure (specify) | D16: 10
C17: Total Add Backs | E17: =SUM(E9:E16) -> 0 | F17: =SUM(F9:F16) -> 0 | G17: =SUM(G9:G16) -> 7369
C18: SECTION C — ALLOWABLE DEDUCTIONS
C19: Capital allowances — SIA (from Cap Allowances sheet) | D19: 11 | E19: ='Cap Allowances'!E43 -> 0 | F19: ='Cap Allowances'!F43 -> 0 | G19: ='Cap Allowances'!G43 -> 0
C20: Wear & Tear allowances (from Cap Allowances sheet) | D20: 12 | E20: ='Cap Allowances'!E62 -> 0 | F20: ='Cap Allowances'!F62 -> 0 | G20: ='Cap Allowances'!G62 -> 0
C21: Bad debts written off (meeting ITA requirements) | D21: 13
C22: Research & development expenditure (approved) | D22: 14
C23: Export incentive deduction (s15(2)(b)) | D23: 15
C24: Other allowable deductions (specify) | D24: 16
C25: Total Deductions | E25: =SUM(E19:E24) -> 0 | F25: =SUM(F19:F24) -> 0 | G25: =SUM(G19:G24) -> 0
C26: SECTION D — EXEMPT INCOME
C27: Dividends from Zimbabwean resident companies | D27: 17
C28: Capital receipts not subject to income tax | D28: 18
C29: Other exempt income (specify) | D29: 19
C30: Total Exempt Income | E30: =SUM(E27:E29) -> 0 | F30: =SUM(F27:F29) -> 0 | G30: =SUM(G27:G29) -> 0
C31: SECTION E — TAXABLE INCOME / (ASSESSED LOSS)
C32: Net income before assessed loss | E32: =E7+E17-E25-E30 -> 0 | F32: =F7+F17-F25-F30 -> 0 | G32: =G7+G17-G25-G30 -> -2211
C33: Less: Assessed loss brought forward (prior year) | D33: 20
C34: TAXABLE INCOME / (ASSESSED LOSS) CARRIED FORWARD | E34: =MAX(E32-E33,0) -> 0 | F34: =MAX(F32-F33,0) -> 0 | G34: =MAX(G32-G33,0) -> 0
C35: Assessed loss to carry forward (if applicable) | E35: =IF(E32-E33<0,ABS(E32-E33),0) -> 0 | F35: =IF(F32-F33<0,ABS(F32-F33),0) -> 0 | G35: =IF(G32-G33<0,ABS(G32-G33),0) -> 2211
C36: SECTION F — INCOME TAX COMPUTATION
C37: Tax rate applicable (%) | D37: 21 | E37: 0.25 | F37: 0.25 | G37: 0.25
C38: Gross income tax (taxable income × rate) | E38: =E34*E37 -> 0 | F38: =F34*F37 -> 0 | G38: =G34*G37 -> 0
C39: AIDS Levy (3% of gross tax) | E39: =E38*0.03 -> 0 | F39: =F38*0.03 -> 0 | G39: =G38*0.03 -> 0
C40: TOTAL TAX LIABILITY (incl. AIDS Levy) | E40: =E38+E39 -> 0 | F40: =F38+F39 -> 0 | G40: =G38+G39 -> 0
C41: SECTION G — DUAL CURRENCY 50/50 RULE (Finance Act s.4A)
...

Sheet Cap Allowances
C2: CAPITAL ALLOWANCES SCHEDULE — SIA & WEAR AND TEAR
C3: Asset Description | D3: Asset Cost | E3: USD | F3: ZiG | G3: Total
C4: SPECIAL INITIAL ALLOWANCE (SIA) — 50% in year of purchase
C5: Manufacturing plant & machinery | E5: =D5*0.5 -> 0 | F5: 0 | G5: =E5+F5 -> 0
C6: Commercial vehicles | E6: =D6*0.5 -> 0 | F6: 0 | G6: =E6+F6 -> 0
C7: Computer equipment & servers | E7: =D7*0.5 -> 0 | F7: 0 | G7: =E7+F7 -> 0
C8: Office furniture & fittings | E8: =D8*0.5 -> 0 | F8: 0 | G8: =E8+F8 -> 0
C9: Other qualifying assets | E9: =D9*0.5 -> 0 | F9: 0 | G9: =E9+F9 -> 0
C10: Total SIA | E10: =SUM(E5:E9) -> 0 | F10: =SUM(F5:F9) -> 0 | G10: =SUM(G5:G9) -> 0
C43: [Linked to Tax Computation Sheet] | E43: =E10 -> 0 | F43: =F10 -> 0 | G43: =G10 -> 0
C62: Wear & Tear [Linked to Tax Computation Sheet] | E62: 0 | F62: 0 | G62: =E62+F62 -> 0

Sheet QPD Recon
C2: QUARTERLY PAYMENT DATES (QPD) RECONCILIATION
C3: QPD | D3: Due Date | E3: USD Paid | F3: ZiG Paid | G3: Receipt / Ref No. | H3: TaRMS Ref
C4: 1st QPD (25%) | D4: 25 March
C5: 2nd QPD (25%) | D5: 25 June
C6: 3rd QPD (25%) | D6: 25 September
C7: 4th QPD (25%) | D7: 20 December
C8: TOTAL QPDs PAID | E8: =SUM(E4:E7) -> 0 | F8: =SUM(F4:F7) -> 0
C10: Total Tax Liability (from Tax Computation) | E10: ='Tax Computation'!E40 -> 0 | F10: ='Tax Computation'!F40 -> 0
C11: Balance of Tax Payable / (Refund Due) | E11: =E10-E8 -> 0 | F11: =F10-F8 -> 0

Sheet WHT Credits
C2: WITHHOLDING TAX (WHT) CREDIT REGISTER
C3: WHT Type | D3: WHT Rate | E3: Gross Amount | F3: WHT Deducted | G3: Certificate Ref
C4: Dividends received | D4: 15%
C5: Interest received | D5: 15%
C6: Contract / service fees | D6: 10%
C7: Rent received | D7: 10%
C8: Royalties | D8: 15%
C9: Other WHT
C10: TOTAL WHT CREDITS | F10: =SUM(F4:F9) -> 0

Sheet Summary
C2: ITF12C — FINAL SUMMARY & RETURN SIGN-OFF
C3: Description | D3: USD (US$) | E3: ZiG (ZWG)
C4: Accounting Profit / (Loss) | D4: ='Tax Computation'!E7 -> 0 | E4: ='Tax Computation'!F7 -> 0
C5: Total Add Backs | D5: ='Tax Computation'!E17 -> 0 | E5: ='Tax Computation'!F17 -> 0
C6: Total Deductions | D6: ='Tax Computation'!E25 -> 0 | E6: ='Tax Computation'!F25 -> 0
C7: Total Exempt Income | D7: ='Tax Computation'!E30 -> 0 | E7: ='Tax Computation'!F30 -> 0
C8: Taxable Income / (Assessed Loss) | D8: ='Tax Computation'!E34 -> 0 | E8: ='Tax Computation'!F34 -> 0
C9: Gross Income Tax | D9: ='Tax Computation'!E38 -> 0 | E9: ='Tax Computation'!F38 -> 0
C10: AIDS Levy (3%) | D10: ='Tax Computation'!E39 -> 0 | E10: ='Tax Computation'!F39 -> 0
C11: Total Tax Liability | D11: ='Tax Computation'!E40 -> 0 | E11: ='Tax Computation'!F40 -> 0
C12: Less: QPD Payments | D12: ='QPD Recon'!E8 -> 0 | E12: ='QPD Recon'!F8 -> 0
C13: Less: WHT Credits | D13: ='WHT Credits'!F10 -> 0 | E13: 0
C14: BALANCE OF TAX PAYABLE / (REFUND) | D14: ='QPD Recon'!E11 -> 0 | E14: ='QPD Recon'!F11 -> 0
A17: DECLARATION
C18: I/We declare that the information furnished in this return and the
C19: accompanying financial statements is true, correct and complete.
C21: Name of authorised signatory: ___________________________
C22: Designation: ___________________________
C23: Signature: ___________________________
C24: Date: ___________________________
C25: Company Stamp (if applicable):___________________________
